Workbook

Sheet tab
A1: ENTITY | B1: SHORTNAME | C1: LABEL | D1: PRIORITY | E1: LEADING | F1: SECURITY
A2: Content | B2: details | D2: 0 | E2: y | F2: PUBLIC
A3: VirtualCollection | B3: details | C3: Details | D3: 0 | E3: y | F3: PUBLIC
A4: Person | B4: details | C4: Profile | D4: 0 | E4: y | F4: PUBLIC
A5: Person | B5: publications | C5: Scholarly works | D5: 2 | E5: n | F5: PUBLIC
A6: Person | B6: editedpublications | C6: Edited Publications | D6: 3 | E6: n | F6: PUBLIC
A7: Person | B7: projects | C7: Projects | D7: 4 | E7: n | F7: PUBLIC
A8: Person | B8: about | C8: About | D8: 5 | E8: n | F8: PUBLIC
A9: Person | B9: orcid | C9: ORCID | D9: 6 | E9: n | F9: OWNER ONLY
A10: Person | B10: indicators | C10: Metrics | D10: 7 | E10: n | F10: PUBLIC
A11: Person | B11: secure | C11: Secured Tab | D11: 8 | E11: n | F11: CUSTOM DATA
A12: OrgUnit | B12: maininformation | C12: Information | D12: 0 | E12: y | F12: PUBLIC
A13: OrgUnit | B13: publications | C13: Scholarly works | D13: 2 | E13: n | F13: PUBLIC
A14: OrgUnit | B14: organizations | C14: Affiliated units | D14: 4 | E14: n | F14: PUBLIC
A15: OrgUnit | B15: people | C15: People | D15: 5 | E15: n | F15: PUBLIC
A16: OrgUnit | B16: projects | C16: Projects | D16: 8 | E16: n | F16: PUBLIC
A17: OrgUnit | B17: rpprojects | C17: Researchers projects | D17: 10 | E17: n | F17: PUBLIC
A18: Project | B18: details | C18: Details | D18: 0 | E18: n | F18: PUBLIC
A19: Project | B19: outputs::projectoutputs | C19: Outputs::Publications | D19: 0 | E19: n | F19: PUBLIC
A20: Project | B20: outputs::fundings | C20: Outputs::Fundings | D20: 10 | E20: n | F20: PUBLIC
A21: Journal | B21: details | C21: Details | D21: 0 | E21: y | F21: PUBLIC
A22: Journal | B22: publications | C22: Publications | D22: 2 | E22: n | F22: PUBLIC
A23: Journal | B23: statistics | C23: Metrics | D23: 3 | E23: n | F23: PUBLIC
A24: Event | B24: details | C24: Details | D24: 0 | E24: y | F24: PUBLIC
A25: Event | B25: publications | C25: Contributions | D25: 2 | E25: n | F25: PUBLIC
A26: Event | B26: statistics | C26: Metrics | D26: 3 | E26: n | F26: PUBLIC
A27: Equipment | B27: details | C27: Details | D27: 0 | E27: n | F27: PUBLIC
A28: Funding | B28: details | C28: Details | D28: 0 | E28: n | F28: PUBLIC
A29: Publication.article | B29: articlemain | C29: Information | D29: 0 | E29: y | F29: PUBLIC
A30: Publication.article | B30: files | C30: Files | D30: 2 | E30: n | F30: PUBLIC
A31: Publication.article | B31: articledetails | C31: Details | D31: 3 | E31: n | F31: PUBLIC
A32: Publication.article | B32: versions | C32: Versions | D32: 4 | E32: n | F32: PUBLIC
A33: Publication.article | B33: statistics | C33: Metrics | D33: 5 | E33: n | F33: PUBLIC
A34: Publication.book | B34: bookmain | C34: Information | D34: 0 | E34: y | F34: PUBLIC
A35: Publication.book | B35: files | C35: Files | D35: 2 | E35: n | F35: PUBLIC
A36: Publication.book | B36: bookdetails | C36: Details | D36: 3 | E36: n | F36: PUBLIC
A37: Publication.book | B37: versions | C37: Versions | D37: 4 | E37: n | F37: PUBLIC
A38: Publication.book | B38: statistics | C38: Metrics | D38: 4 | E38: n | F38: PUBLIC
A39: Publication.conference | B39: conferencemain | C39: Information | D39: 0 | E39: y | F39: PUBLIC
A40: Publication.conference | B40: files | C40: Files | D40: 2 | E40: n | F40: PUBLIC
...

Sheet tab2box
A1: ENTITY | B1: TAB | C1: ROW | D1: ROW_STYLE | E1: CELL_STYLE | F1: BOXES
A2: Content | B2: details | C2: 1 | F2: heading
A3: Content | B3: details | C3: 3 | F3: details
A4: VirtualCollection | B4: details | C4: 1 | F4: title
A5: VirtualCollection | B5: details | C5: 2 | F5: details
A6: VirtualCollection | B6: details | C6: 3 | F6: publications
A7: Person | B7: details | C7: 1 | F7: heading
A8: Person | B8: details | C8: 2 | F8: namecard
A9: Person | B9: publications | C9: 1 | F9: researchoutputs
A10: Person | B10: editedpublications | C10: 1 | F10: editedresearchoutputs
A11: Person | B11: about | C11: 1 | E11: mx-3 col-md-8 col-12 | F11: researcherprofile
A12: Person | B12: about | C12: 1 | E12: col-md-3 col-12 | F12: gscholar
A13: Person | B13: projects | C13: 1 | F13: projects
A14: Person | B14: indicators | C14: 1 | E14: mx-3 col-9 justify-content-md-center | F14: usagemetrics
A15: Person | B15: indicators | C15: 2 | E15: mx-3 col-9 justify-content-md-center | F15: metrics
A16: Person | B16: secure | C16: 1 | F16: secure
A17: OrgUnit | B17: maininformation | C17: 1 | F17: heading
A18: OrgUnit | B18: maininformation | C18: 2 | F18: details
A19: OrgUnit | B19: maininformation | C19: 3 | D19: p-4 | F19: description
A20: OrgUnit | B20: organizations | C20: 1 | F20: organizations
A21: OrgUnit | B21: publications | C21: 1 | F21: publications
A22: OrgUnit | B22: people | C22: 1 | F22: people
A23: OrgUnit | B23: projects | C23: 1 | F23: projects
A24: OrgUnit | B24: rpprojects | C24: 1 | F24: rpprojects
A25: Journal | B25: details | C25: 1 | F25: heading
A26: Journal | B26: details | C26: 2 | F26: details
A27: Journal | B27: details | C27: 3 | D27: p-4 | F27: description
A28: Journal | B28: statistics | C28: 1 | F28: metrics
A29: Journal | B29: publications | C29: 1 | F29: researchoutputs
A30: Event | B30: details | C30: 1 | F30: heading
A31: Event | B31: details | C31: 2 | F31: details
A32: Event | B32: details | C32: 3 | D32: p-4 | F32: description
A33: Event | B33: statistics | C33: 1 | F33: metrics
A34: Event | B34: publications | C34: 1 | F34: researchoutputs
A35: Publication | B35: files | C35: 1 | F35: publicationfiles
A36: Publication | B36: statistics | C36: 1 | E36: mx-3 col-9 justify-content-md-center | F36: metrics
A37: Publication | B37: statistics | C37: 2 | E37: mx-3 col-9 justify-content-md-center | F37: usagemetrics
A38: Publication | B38: statistics | C38: 3 | E38: mx-3 col-9 justify-content-md-center | F38: allmetrics
A39: Publication | B39: versions | C39: 1 | D39: mt-5 | F39: versioning
A40: Publication | B40: articlemain | C40: 1 | E40: col-12 | F40: articleheading
...

Sheet box
A1: ENTITY | B1: COLLAPSED | C1: TYPE | D1: SHORTNAME | E1: LABEL | F1: CONTAINER | G1: MINOR | H1: SECURITY | I1: STYLE
A2: Content | B2: n | C2: METADATA | D2: heading | F2: n | G2: n | H2: PUBLIC
A3: Content | B3: n | C3: METADATA | D3: details | F3: n | G3: n | H3: PUBLIC
A4: VirtualCollection | B4: n | C4: METADATA | D4: title | F4: n | G4: n | H4: PUBLIC
A5: VirtualCollection | B5: n | C5: METADATA | D5: details | E5: Details | F5: n | G5: n | H5: PUBLIC
A6: VirtualCollection | B6: n | C6: RELATION | D6: publications | E6: Publications | F6: n | G6: n | H6: PUBLIC
A7: Person | B7: n | C7: METADATA | D7: heading | F7: n | G7: n | H7: PUBLIC | I7: h2
A8: Person | B8: n | C8: METADATA | D8: namecard | F8: n | G8: n | H8: PUBLIC | I8: item-detail
A9: Person | B9: n | C9: RELATION | D9: researchoutputs | F9: n | G9: n | H9: PUBLIC
A10: Person | B10: n | C10: RELATION | D10: editedresearchoutputs | F10: n | G10: n | H10: PUBLIC
A11: Person | B11: n | C11: METRICS | D11: usagemetrics | E11: Usage metrics | F11: n | G11: n | H11: PUBLIC
A12: Person | B12: n | C12: METRICS | D12: metrics | E12: Metrics | F12: n | G12: n | H12: PUBLIC
A13: Person | B13: n | C13: METRICS | D13: gscholar | E13: Google Scholar | F13: n | G13: n | H13: PUBLIC
A14: Person | B14: n | C14: METADATA | D14: researcherprofile | E14: Profile | F14: n | G14: n | H14: PUBLIC
A15: Person | B15: n | C15: RELATION | D15: projects | E15: Projects | F15: n | G15: n | H15: PUBLIC
A16: Person | B16: n | C16: METADATA | D16: secure | E16: Secured box | F16: n | G16: y | H16: CUSTOM DATA
A17: OrgUnit | B17: n | C17: METADATA | D17: heading | F17: n | G17: n | H17: PUBLIC | I17: h2
A18: OrgUnit | B18: n | C18: METADATA | D18: details | E18: Details | F18: n | G18: n | H18: PUBLIC | I18: item-detail
A19: OrgUnit | B19: n | C19: METADATA | D19: description | E19: Description | F19: n | G19: n | H19: PUBLIC
A20: OrgUnit | B20: n | C20: RELATION | D20: organizations | E20: Affiliated EPFL Units | F20: n | G20: n | H20: PUBLIC
A21: OrgUnit | B21: n | C21: RELATION | D21: publications | E21: Scholarly works | F21: n | G21: n | H21: PUBLIC
A22: OrgUnit | B22: n | C22: RELATION | D22: projects | E22: OrgUnit funded Projects | F22: n | G22: n | H22: PUBLIC
A23: OrgUnit | B23: n | C23: RELATION | D23: rpprojects | E23: OrgUnit's Researchers projects | F23: n | G23: n | H23: PUBLIC
A24: OrgUnit | B24: n | C24: RELATION | D24: people | E24: Members | F24: n | G24: n | H24: PUBLIC
A25: Journal | B25: n | C25: METADATA | D25: heading | F25: n | G25: n | H25: PUBLIC
A26: Journal | B26: n | C26: METADATA | D26: details | F26: n | G26: n | H26: PUBLIC | I26: item-detail
A27: Journal | B27: n | C27: METADATA | D27: description | E27: Description | F27: n | G27: n | H27: PUBLIC
A28: Journal | B28: n | C28: METRICS | D28: metrics | F28: n | G28: n | H28: PUBLIC
A29: Journal | B29: n | C29: RELATION | D29: researchoutputs | E29: Scholarly works | F29: n | G29: n | H29: PUBLIC
A30: Event | B30: n | C30: METADATA | D30: heading | F30: n | G30: n | H30: PUBLIC
A31: Event | B31: n | C31: METADATA | D31: details | F31: n | G31: n | H31: PUBLIC | I31: item-detail
A32: Event | B32: n | C32: METADATA | D32: description | E32: Description | F32: n | G32: n | H32: PUBLIC
A33: Event | B33: n | C33: METRICS | D33: metrics | F33: n | G33: n | H33: PUBLIC
A34: Event | B34: n | C34: RELATION | D34: researchoutputs | E34: Scholarly works | F34: n | G34: n | H34: PUBLIC
A35: Publication | B35: n | C35: METADATA | D35: abstract | F35: n | G35: n | H35: PUBLIC
A36: Publication | B36: n | C36: METADATA | D36: handle | F36: n | G36: n | H36: PUBLIC | I36: p-3 justify-content-md-center
A37: Publication | B37: n | C37: METADATA | D37: publicationfiles | F37: n | G37: n | H37: PUBLIC
A38: Publication | B38: n | C38: METRICS | D38: usagemetrics | F38: n | G38: n | H38: PUBLIC
A39: Publication | B39: n | C39: METRICS | D39: metrics | F39: n | G39: n | H39: PUBLIC
A40: Publication | B40: n | C40: METRICS | D40: allmetrics | F40: n | G40: n | H40: PUBLIC
...

Sheet box2hierarchicalvocabulary
A1: ENTITY | B1: BOX | C1: VOCABULARY | D1: METADATA

Sheet box2metadata
A1: ENTITY | B1: BOX | C1: ROW | D1: CELL | E1: FIELDTYPE | F1: METADATA | G1: VALUE | H1: BUNDLE | I1: LABEL | J1: LABEL_AS_HEADING | K1: RENDERING | L1: VALUES_INLINE | M1: ROW_STYLE | N1: CELL_STYLE | O1: STYLE_LABEL | P1: STYLE_VALUE
A2: Content | B2: heading | C2: 1 | D2: 1 | E2: METADATA | F2: dc.title | J2: n | K2: heading | L2: n | N2: col-10 px-2 | P2: h2
A3: Content | B3: details | C3: 1 | D3: 1 | E3: METADATA | F3: dc.description | J3: n | K3: markdown | L3: n | N3: col-12 p-3 | O3: font-weight-bold col-3
A4: Content | B4: details | C4: 2 | D4: 1 | E4: METADATAGROUP | F4: epfl.content.link | J4: n | K4: table | L4: n | N4: pt-3 | O4: font-weight-bold col-3
A5: Content | B5: details | C5: 3 | D5: 1 | E5: BITSTREAM | F5: dc.type | G5: !logo | H5: ORIGINAL | J5: n | K5: advancedattachment | L5: n | N5: p-3 | O5: font-weight-bold col-3
A6: VirtualCollection | B6: title | C6: 1 | D6: 1 | E6: METADATA | F6: dc.title | J6: y | K6: heading | L6: n | O6: font-weight-bold col-3
A7: VirtualCollection | B7: details | C7: 1 | D7: 1 | E7: METADATA | F7: dc.description | J7: n | K7: markdown | L7: n | N7: py-2 | O7: font-weight-bold col-3
A8: Person | B8: heading | C8: 1 | D8: 1 | E8: METADATA | F8: dc.title | J8: n | K8: heading | L8: n | O8: font-weight-bold col-3 | P8: h2
A9: Person | B9: namecard | C9: 2 | D9: 1 | E9: BITSTREAM | F9: dc.type | G9: personal picture | H9: ORIGINAL | J9: n | K9: thumbnail | L9: n | N9: col-lg-2 col-sm-3 col-1 | O9: font-weight-bold col-3 | P9: float-left d-none d-md-block
A10: Person | B10: namecard | C10: 2 | D10: 2 | E10: METADATA | F10: dc.title | I10: Name | J10: n | L10: n | O10: font-weight-bold text-left text-md-right p-0 | P10: text-muted flex-sm-shrink-1 pl-1
A11: Person | B11: namecard | C11: 2 | D11: 2 | E11: METADATA | F11: crisrp.name | I11: Official Name | J11: n | L11: n | O11: font-weight-bold text-left text-md-right p-0 | P11: text-muted flex-sm-shrink-1 pl-1
A12: Person | B12: namecard | C12: 2 | D12: 2 | E12: METADATA | F12: crisrp.name.translated | I12: Translated name | J12: n | L12: n | O12: font-weight-bold text-left text-md-right p-0 | P12: text-muted flex-sm-shrink-1 pl-1
A13: Person | B13: namecard | C13: 2 | D13: 2 | E13: METADATA | F13: person.jobTitle | I13: Main position | J13: n | L13: n | O13: font-weight-bold text-left text-md-right p-0 | P13: text-muted flex-sm-shrink-1 pl-1
A14: Person | B14: namecard | C14: 2 | D14: 2 | E14: METADATA | F14: person.affiliation.name | I14: Main EPFL affiliation | J14: n | K14: crisref | L14: n | O14: font-weight-bold text-left text-md-right p-0 | P14: text-muted flex-sm-shrink-1 pl-1
A15: Person | B15: namecard | C15: 2 | D15: 2 | E15: METADATA | F15: person.email | I15: Email | J15: n | K15: crisref.email | L15: n | O15: font-weight-bold text-left text-md-right p-0 | P15: text-muted flex-sm-shrink-1 pl-1
A16: Person | B16: namecard | C16: 2 | D16: 2 | E16: METADATA | F16: person.identifier.orcid | I16: ORCID | J16: n | K16: orcid | L16: n | O16: font-weight-bold text-left text-md-right p-0 | P16: text-muted flex-sm-shrink-1 pl-1
A17: Person | B17: namecard | C17: 2 | D17: 2 | E17: METADATA | F17: person.identifier.openalex | I17: OpenAlexID | J17: n | K17: link | L17: n | O17: font-weight-bold text-left text-md-right p-0 | P17: text-muted flex-sm-shrink-1 pl-1
A18: Person | B18: namecard | C18: 2 | D18: 2 | E18: METADATA | F18: person.identifier.scopus-author-id | I18: ScopusID | J18: n | K18: identifier.scopus | L18: n | O18: font-weight-bold text-left text-md-right p-0 | P18: text-muted flex-sm-shrink-1 pl-1
A19: Person | B19: namecard | C19: 2 | D19: 2 | E19: METADATA | F19: person.identifier.rid | I19: ResearcherID | J19: n | K19: identifier.researcherid | L19: n | O19: font-weight-bold text-left text-md-right p-0 | P19: text-muted flex-sm-shrink-1 pl-1
A20: Person | B20: namecard | C20: 2 | D20: 2 | E20: METADATA | F20: epfl.sciper.active | I20: EPFL member | J20: n | K20: valuepair.person_status | L20: n | O20: font-weight-bold text-left text-md-right p-0 | P20: flex-sm-shrink-1 pl-1 badge badge-primary
A21: Person | B21: researcherprofile | C21: 1 | D21: 1 | E21: METADATA | F21: dc.description.abstract | I21: Biography | J21: n | K21: markdown | L21: n
A22: Person | B22: researcherprofile | C22: 2 | D22: 1 | E22: METADATA | F22: dc.subject | I22: Research Interests | J22: n | K22: tag | L22: n | O22: font-weight-bold col-3 | P22: small
A23: Person | B23: researcherprofile | C23: 3 | D23: 1 | E23: METADATA | F23: oairecerif.identifier.url | I23: Personal website | J23: n | K23: link | L23: n | N23: pt-2 | O23: font-weight-bold col-3 | P23: text-break
A24: Person | B24: researcherprofile | C24: 4 | D24: 1 | E24: METADATAGROUP | F24: oairecerif.person.affiliation | I24: EPFL affiliations | J24: n | K24: table | L24: n | N24: pt-4 | O24: font-weight-bold col-3
A25: Person | B25: secure | C25: 1 | D25: 1 | E25: METADATA | F25: cris.policy.eperson | J25: n | L25: n | O25: font-weight-bold col-3
A26: OrgUnit | B26: heading | C26: 1 | D26: 1 | E26: METADATA | F26: dc.title | J26: n | K26: heading | L26: n | O26: font-weight-bold col-3 | P26: h2
A27: OrgUnit | B27: details | C27: 1 | D27: 1 | E27: BITSTREAM | F27: dc.type | G27: logo | H27: ORIGINAL | J27: n | K27: thumbnail | L27: n | N27: col-lg-2 col-sm-3 col-1 | O27: font-weight-bold col-3 | P27: float-left d-none d-md-block
A28: OrgUnit | B28: details | C28: 1 | D28: 2 | E28: METADATA | F28: oairecerif.acronym | I28: Acronym | J28: n | L28: n | O28: font-weight-bold text-left text-md-right p-0 | P28: text-muted flex-sm-shrink-1 pl-1
A29: OrgUnit | B29: details | C29: 1 | D29: 2 | E29: METADATA | F29: epfl.unit.alias | I29: Other aliases | J29: n | L29: n | O29: font-weight-bold text-left text-md-right p-0 | P29: text-muted flex-sm-shrink-1 pl-1
A30: OrgUnit | B30: details | C30: 1 | D30: 2 | E30: METADATA | F30: crisou.director | I30: Director | J30: n | K30: crisref | L30: n | O30: font-weight-bold text-left text-md-right p-0 | P30: text-muted flex-sm-shrink-1 pl-1
A31: OrgUnit | B31: details | C31: 1 | D31: 2 | E31: METADATA | F31: organization.parentOrganization | I31: Parent unit | J31: n | K31: crisref | L31: n | O31: font-weight-bold text-left text-md-right p-0 | P31: text-muted flex-sm-shrink-1 pl-1
A32: OrgUnit | B32: details | C32: 1 | D32: 2 | E32: METADATA | F32: organization.foundingDate | I32: Founding date | J32: n | K32: date | L32: n | O32: font-weight-bold text-left text-md-right p-0 | P32: text-muted flex-sm-shrink-1 pl-1
A33: OrgUnit | B33: details | C33: 1 | D33: 2 | E33: METADATA | F33: organization.closingDate | I33: Closing date | J33: n | K33: date | L33: n | O33: font-weight-bold text-left text-md-right p-0 | P33: text-muted flex-sm-shrink-1 pl-1
A34: OrgUnit | B34: details | C34: 1 | D34: 2 | E34: METADATA | F34: oairecerif.identifier.url | I34: Website | J34: n | K34: link | L34: n | O34: font-weight-bold text-left text-md-right p-0 | P34: text-muted flex-sm-shrink-1 pl-1 text-break
A35: OrgUnit | B35: details | C35: 1 | D35: 2 | E35: METADATA | F35: epfl.orgUnit.active | I35: Status | J35: n | K35: valuepair.orgunit_status | L35: n | O35: font-weight-bold text-left text-md-right p-0 | P35: flex-sm-shrink-1 pl-1 badge badge-primary
A36: OrgUnit | B36: description | C36: 1 | D36: 1 | E36: METADATA | F36: dc.description.abstract | J36: y | K36: markdown | L36: n | N36: pt-3
A37: Journal | B37: heading | C37: 1 | D37: 1 | E37: METADATA | F37: dc.title | J37: n | K37: heading | L37: n | O37: font-weight-bold col-3 | P37: h2
A38: Journal | B38: details | C38: 1 | D38: 1 | E38: BITSTREAM | F38: dc.type | G38: logo | H38: ORIGINAL | J38: n | K38: thumbnail | L38: n | N38: col-lg-2 col-sm-3 col-1 | O38: font-weight-bold col-3 | P38: float-left d-none d-md-block
A39: Journal | B39: details | C39: 1 | D39: 2 | E39: METADATA | F39: dc.publisher | I39: Publisher | J39: n | L39: n | O39: font-weight-bold text-left text-md-right p-0 | P39: text-muted flex-sm-shrink-1 pl-1
A40: Journal | B40: details | C40: 1 | D40: 2 | E40: METADATA | F40: dc.identifier.issn | I40: ISSN | J40: n | L40: n | O40: font-weight-bold text-left text-md-right p-0 | P40: text-muted flex-sm-shrink-1 pl-1
...

Sheet metadatagroups
A1: ENTITY | B1: PARENT | C1: FIELDTYPE | D1: METADATA | E1: VALUE | F1: BUNDLE | G1: LABEL | H1: RENDERING | I1: STYLE_LABEL | J1: STYLE_VALUE
A2: Content | B2: epfl.content.link | C2: METADATA | D2: epfl.content.linkdescription | G2: Description | H2: text | I2: font-weight-bold
A3: Content | B3: epfl.content.link | C3: METADATA | D3: epfl.content.link | G3: Link | H3: link | I3: font-weight-bold
A4: Person | B4: oairecerif.person.affiliation | C4: METADATA | D4: oairecerif.affiliation.role | G4: Position | H4: text | I4: font-weight-bold
A5: Person | B5: oairecerif.person.affiliation | C5: METADATA | D5: oairecerif.person.affiliation | G5: EPFL Unit | H5: crisref | I5: font-weight-bold
A6: Person | B6: oairecerif.person.affiliation | C6: METADATA | D6: oairecerif.affiliation.endDate | G6: Affiliation end date | H6: date | I6: font-weight-bold
A7: Publication | B7: dc.date.issued | C7: METADATA | D7: dc.date.issued | H7: date | I7: font-weight-bold
A8: Publication | B8: dc.date.issued | C8: METADATA | D8: dc.relation.ispartof | H8: crisref | I8: font-weight-bold
A9: Publication | B9: dc.relation.journal | C9: METADATA | D9: dc.date.issued | H9: date | I9: font-weight-bold
A10: Publication | B10: dc.relation.journal | C10: METADATA | D10: dc.relation.journal | H10: crisref | I10: font-weight-bold
A11: Publication | B11: epfl.url | C11: METADATA | D11: epfl.url.description | G11: Additional link | H11: text | I11: font-weight-bold
A12: Publication | B12: epfl.url | C12: METADATA | D12: epfl.url | H12: link | I12: font-weight-bold
A13: Publication | B13: oairecerif.funder | C13: METADATA | D13: oairecerif.funder | G13: Funder | I13: font-weight-bold
A14: Publication | B14: oairecerif.funder | C14: METADATA | D14: dc.relation.funding | G14: Grant Name | I14: font-weight-bold
A15: Publication | B15: oairecerif.funder | C15: METADATA | D15: dc.relation.grantno | G15: Grant Number | I15: font-weight-bold
A16: Publication | B16: oairecerif.funder | C16: METADATA | D16: crisfund.award.uri | G16: Grant URL | H16: link | I16: font-weight-bold
A17: Publication | B17: dc.contributor.author | C17: METADATA | D17: dc.contributor.author | H17: crisref | I17: font-weight-bold
A18: Publication | B18: dc.contributor.author | C18: METADATA | D18: oairecerif.author.affiliation | I18: font-weight-bold | J18: font-weight-bold
A19: Publication | B19: dc.relation.conference | C19: METADATA | D19: dc.relation.conference | G19: Event name | H19: crisref | I19: font-weight-bold
A20: Publication | B20: dc.relation.conference | C20: METADATA | D20: oairecerif.acronym | G20: Event acronym | I20: font-weight-bold
A21: Publication | B21: dc.relation.conference | C21: METADATA | D21: oaire.citation.conferencePlace | G21: Event place | I21: font-weight-bold
A22: Publication | B22: dc.relation.conference | C22: METADATA | D22: oaire.citation.conferenceDate | G22: Event date | I22: font-weight-bold
A23: Publication | B23: epfl.award | C23: METADATA | D23: epfl.award | G23: Award | H23: text | I23: font-weight-bold
A24: Publication | B24: epfl.award | C24: METADATA | D24: epfl.award.date | H24: date | I24: font-weight-bold
A25: Publication | B25: datacite.relatedIdentifier | C25: METADATA | D25: datacite.relationType | G25: Relation | I25: font-weight-bold
A26: Publication | B26: datacite.relatedIdentifier | C26: METADATA | D26: dc.relation.title | G26: Related work | I26: font-weight-bold
A27: Publication | B27: datacite.relatedIdentifier | C27: METADATA | D27: datacite.relatedIdentifier | G27: URL/DOI | H27: link | I27: font-weight-bold
A28: Product | B28: dc.type | C28: METADATA | D28: dc.type | H28: valuepair.product-coar-types
A29: Product | B29: dc.type | C29: METADATA | D29: datacite.rights
A30: Product | B30: dc.contributor.author | C30: METADATA | D30: dc.contributor.author | H30: crisref | I30: font-weight-bold
A31: Product | B31: dc.contributor.author | C31: METADATA | D31: oairecerif.author.affiliation | I31: font-weight-bold | J31: font-weight-bold
A32: Product | B32: dc.publisher | C32: METADATA | D32: dc.date.issued | H32: date
A33: Product | B33: dc.publisher | C33: METADATA | D33: dc.publisher | H33: crisref
A34: Product | B34: epfl.url | C34: METADATA | D34: epfl.url.description | G34: Link description | I34: font-weight-bold
A35: Product | B35: epfl.url | C35: METADATA | D35: epfl.url | G35: URL | H35: link | I35: font-weight-bold
A36: Product | B36: dc.relation.conference | C36: METADATA | D36: dc.relation.conference | G36: Event name | H36: crisref | I36: font-weight-bold
A37: Product | B37: dc.relation.conference | C37: METADATA | D37: oairecerif.acronym | G37: Event acronym | I37: font-weight-bold
A38: Product | B38: dc.relation.conference | C38: METADATA | D38: oaire.citation.conferencePlace | G38: Event place | I38: font-weight-bold
A39: Product | B39: dc.relation.conference | C39: METADATA | D39: oaire.citation.conferenceDate | G39: Event date | I39: font-weight-bold
A40: Product | B40: oairecerif.funder | C40: METADATA | D40: oairecerif.funder | G40: Funder | I40: font-weight-bold
...

Sheet box2metrics
A1: ENTITY | B1: BOX | C1: METRIC_TYPE
A2: Person | B2: metrics | C2: scopus-author-h-index, scopus-author-coauthor-count, scopus-author-cited-count, scopus-author-citation-count, scopus-author-document-count, wosPersonCitation
A3: Person | B3: gscholar | C3: google-scholar
A4: Person | B4: usagemetrics | C4: view, embedded-view
A5: Project | B5: metrics | C5: view, embedded-view
A6: Event | B6: metrics | C6: view, embedded-view
A7: Journal | B7: metrics | C7: view, embedded-view
A8: Equipment | B8: metrics | C8: view, embedded-view
A9: Funding | B9: metrics | C9: view, embedded-view
A10: Publication | B10: usagemetrics | C10: view, embedded-view, download, embedded-download
A11: Publication | B11: usagemetrics | C11: wosCitation, scopusCitation
A12: Publication | B12: allmetrics | C12: altmetric
... A15: Patent | B15: usagemetrics | C15: view, embedded-view

Sheet tabpolicy
A1: ENTITY | B1: SHORTNAME | C1: METADATA | D1: GROUP
A2: Person | B2: secure | C2: cris.policy.group

Sheet boxpolicy
A1: ENTITY | B1: SHORTNAME | C1: METADATA | D1: GROUP
A2: Person | B2: secure | C2: cris.policy.eperson
A3: Person | B3: secure | C3: cris.policy.eperson
A4: Funding | B4: financialdata | C4: crisfund.coinvestigators
A5: Funding | B5: financialdata | C5: crisfund.investigators

Sheet utilsdata
A1: BOX-TYPES | B1: METADATA-RENDERING | C1: Security
A2: RELATION | B2: heading | C2: PUBLIC
A3: METADATA | B3: text | C3: ADMINISTRATOR
A4: METRICS | B4: longtext | C4: OWNER ONLY
A5: IIIFVIEWER | B5: link | C5: OWNER & ADMINISTRATOR
B6: link.label | C6: CUSTOM DATA
B7: date | C7: CUSTOM DATA & ADMINISTRATOR
B8: identifier
B9: crisref
B10: thumbnail
B11: attachment
B12: tag

Sheet tab_i18n
A1: PREFIX | B1: AUTOGENERATED I18N keys
A2: layout.tab.header. | B2: =IF(OR(ISBLANK(tab!$C4),EXACT(MID(tab!$C4,1,LEN($A$2)),$A$2)),"",""""&$A$2&tab!$A4&"."&tab!$B4&""": """&SUBSTITUTE(tab!$C4,"""","\""")&""",") -> "layout.tab.header.Person.details": "Profile",
B3: =IF(OR(ISBLANK(tab!$C5),EXACT(MID(tab!$C5,1,LEN($A$2)),$A$2)),"",""""&$A$2&tab!$A5&"."&tab!$B5&""": """&SUBSTITUTE(tab!$C5,"""","\""")&""",") -> "layout.tab.header.Person.publications": "Scholarly works",
B4: =IF(OR(ISBLANK(tab!$C6),EXACT(MID(tab!$C6,1,LEN($A$2)),$A$2)),"",""""&$A$2&tab!$A6&"."&tab!$B6&""": """&SUBSTITUTE(tab!$C6,"""","\""")&""",") -> "layout.tab.header.Person.editedpublications": "Edited Publications",
B5: =IF(OR(ISBLANK(tab!$C7),EXACT(MID(tab!$C7,1,LEN($A$2)),$A$2)),"",""""&$A$2&tab!$A7&"."&tab!$B7&""": """&SUBSTITUTE(tab!$C7,"""","\""")&""",") -> "layout.tab.header.Person.projects": "Projects",
B6: =IF(OR(ISBLANK(tab!$C8),EXACT(MID(tab!$C8,1,LEN($A$2)),$A$2)),"",""""&$A$2&tab!$A8&"."&tab!$B8&""": """&SUBSTITUTE(tab!$C8,"""","\""")&""",") -> "layout.tab.header.Person.about": "About",
B7: =IF(OR(ISBLANK(tab!$C9),EXACT(MID(tab!$C9,1,LEN($A$2)),$A$2)),"",""""&$A$2&tab!$A9&"."&tab!$B9&""": """&SUBSTITUTE(tab!$C9,"""","\""")&""",") -> "layout.tab.header.Person.orcid": "ORCID",
B8: =IF(OR(ISBLANK(tab!$C10),EXACT(MID(tab!$C10,1,LEN($A$2)),$A$2)),"",""""&$A$2&tab!$A10&"."&tab!$B10&""": """&SUBSTITUTE(tab!$C10,"""","\""")&""",") -> "layout.tab.header.Person.indicators": "Metrics",
B9: =IF(OR(ISBLANK(tab!$C11),EXACT(MID(tab!$C11,1,LEN($A$2)),$A$2)),"",""""&$A$2&tab!$A11&"."&tab!$B11&""": """&SUBSTITUTE(tab!$C11,"""","\""")&""",") -> "layout.tab.header.Person.secure": "Secured Tab",
B10: =IF(OR(ISBLANK(tab!$C12),EXACT(MID(tab!$C12,1,LEN($A$2)),$A$2)),"",""""&$A$2&tab!$A12&"."&tab!$B12&""": """&SUBSTITUTE(tab!$C12,"""","\""")&""",") -> "layout.tab.header.OrgUnit.maininformation": "Information",
B11: =IF(OR(ISBLANK(tab!$C14),EXACT(MID(tab!$C14,1,LEN($A$2)),$A$2)),"",""""&$A$2&tab!$A14&"."&tab!$B14&""": """&SUBSTITUTE(tab!$C14,"""","\""")&""",") -> "layout.tab.header.OrgUnit.organizations": "Affiliated units",
B12: =IF(OR(ISBLANK(tab!$C13),EXACT(MID(tab!$C13,1,LEN($A$2)),$A$2)),"",""""&$A$2&tab!$A13&"."&tab!$B13&""": """&SUBSTITUTE(tab!$C13,"""","\""")&""",") -> "layout.tab.header.OrgUnit.publications": "Scholarly works",
B13: =IF(OR(ISBLANK(tab!$C15),EXACT(MID(tab!$C15,1,LEN($A$2)),$A$2)),"",""""&$A$2&tab!$A15&"."&tab!$B15&""": """&SUBSTITUTE(tab!$C15,"""","\""")&""",") -> "layout.tab.header.OrgUnit.people": "People",
B14: =IF(OR(ISBLANK(tab!$C16),EXACT(MID(tab!$C16,1,LEN($A$2)),$A$2)),"",""""&$A$2&tab!$A16&"."&tab!$B16&""": """&SUBSTITUTE(tab!$C16,"""","\""")&""",") -> "layout.tab.header.OrgUnit.projects": "Projects",
B15: =IF(OR(ISBLANK(tab!$C17),EXACT(MID(tab!$C17,1,LEN($A$2)),$A$2)),"",""""&$A$2&tab!$A17&"."&tab!$B17&""": """&SUBSTITUTE(tab!$C17,"""","\""")&""",") -> "layout.tab.header.OrgUnit.rpprojects": "Researchers projects",
B16: =IF(OR(ISBLANK(tab!$C18),EXACT(MID(tab!$C18,1,LEN($A$2)),$A$2)),"",""""&$A$2&tab!$A18&"."&tab!$B18&""": """&SUBSTITUTE(tab!$C18,"""","\""")&""",") -> "layout.tab.header.Project.details": "Details",
B17: =IF(OR(ISBLANK(tab!$C19),EXACT(MID(tab!$C19,1,LEN($A$2)),$A$2)),"",""""&$A$2&tab!$A19&"."&tab!$B19&""": """&SUBSTITUTE(tab!$C19,"""","\""")&""",") -> "layout.tab.header.Project.outputs::projectoutputs": "Outputs::Publications",
B18: =IF(OR(ISBLANK(tab!$C20),EXACT(MID(tab!$C20,1,LEN($A$2)),$A$2)),"",""""&$A$2&tab!$A20&"."&tab!$B20&""": """&SUBSTITUTE(tab!$C20,"""","\""")&""",") -> "layout.tab.header.Project.outputs::fundings": "Outputs::Fundings",
B19: =IF(OR(ISBLANK(tab!$C21),EXACT(MID(tab!$C21,1,LEN($A$2)),$A$2)),"",""""&$A$2&tab!$A21&"."&tab!$B21&""": """&SUBSTITUTE(tab!$C21,"""","\""")&""",") -> "layout.tab.header.Journal.details": "Details",
B20: =IF(OR(ISBLANK(tab!$C22),EXACT(MID(tab!$C22,1,LEN($A$2)),$A$2)),"",""""&$A$2&tab!$A22&"."&tab!$B22&""": """&SUBSTITUTE(tab!$C22,"""","\""")&""",") -> "layout.tab.header.Journal.publications": "Publications",
B21: =IF(OR(ISBLANK(tab!$C23),EXACT(MID(tab!$C23,1,LEN($A$2)),$A$2)),"",""""&$A$2&tab!$A23&"."&tab!$B23&""": """&SUBSTITUTE(tab!$C23,"""","\""")&""",") -> "layout.tab.header.Journal.statistics": "Metrics",
B22: =IF(OR(ISBLANK(tab!$C24),EXACT(MID(tab!$C24,1,LEN($A$2)),$A$2)),"",""""&$A$2&tab!$A24&"."&tab!$B24&""": """&SUBSTITUTE(tab!$C24,"""","\""")&""",") -> "layout.tab.header.Event.details": "Details",
B23: =IF(OR(ISBLANK(tab!$C25),EXACT(MID(tab!$C25,1,LEN($A$2)),$A$2)),"",""""&$A$2&tab!$A25&"."&tab!$B25&""": """&SUBSTITUTE(tab!$C25,"""","\""")&""",") -> "layout.tab.header.Event.publications": "Contributions",
B24: =IF(OR(ISBLANK(tab!$C26),EXACT(MID(tab!$C26,1,LEN($A$2)),$A$2)),"",""""&$A$2&tab!$A26&"."&tab!$B26&""": """&SUBSTITUTE(tab!$C26,"""","\""")&""",") -> "layout.tab.header.Event.statistics": "Metrics",
... B29: =IF(OR(ISBLANK(tab!$C31),EXACT(MID(tab!$C31,1,LEN($A$2)),$A$2)),"",""""&$A$2&tab!$A31&"."&tab!$B31&""": """&SUBSTITUTE(tab!$C31,"""","\""")&""",") -> "layout.tab.header.Publication.article.articledetails": "Details",
B30: =IF(OR(ISBLANK(tab!$C33),EXACT(MID(tab!$C33,1,LEN($A$2)),$A$2)),"",""""&$A$2&tab!$A33&"."&tab!$B33&""": """&SUBSTITUTE(tab!$C33,"""","\""")&""",") -> "layout.tab.header.Publication.article.statistics": "Metrics",
B31: =IF(OR(ISBLANK(tab!$C34),EXACT(MID(tab!$C34,1,LEN($A$2)),$A$2)),"",""""&$A$2&tab!$A34&"."&tab!$B34&""": """&SUBSTITUTE(tab!$C34,"""","\""")&""",") -> "layout.tab.header.Publication.book.bookmain": "Information",
B32: =IF(OR(ISBLANK(tab!$C35),EXACT(MID(tab!$C35,1,LEN($A$2)),$A$2)),"",""""&$A$2&tab!$A35&"."&tab!$B35&""": """&SUBSTITUTE(tab!$C35,"""","\""")&""",") -> "layout.tab.header.Publication.book.files": "Files",
B33: =IF(OR(ISBLANK(tab!$C36),EXACT(MID(tab!$C36,1,LEN($A$2)),$A$2)),"",""""&$A$2&tab!$A36&"."&tab!$B36&""": """&SUBSTITUTE(tab!$C36,"""","\""")&""",") -> "layout.tab.header.Publication.book.bookdetails": "Details",
B34: =IF(OR(ISBLANK(tab!$C38),EXACT(MID(tab!$C38,1,LEN($A$2)),$A$2)),"",""""&$A$2&tab!$A38&"."&tab!$B38&""": """&SUBSTITUTE(tab!$C38,"""","\""")&""",") -> "layout.tab.header.Publication.book.statistics": "Metrics",
B35: =IF(OR(ISBLANK(tab!$C39),EXACT(MID(tab!$C39,1,LEN($A$2)),$A$2)),"",""""&$A$2&tab!$A39&"."&tab!$B39&""": """&SUBSTITUTE(tab!$C39,"""","\""")&""",") -> "layout.tab.header.Publication.conference.conferencemain": "Information",
B36: =IF(OR(ISBLANK(tab!$C40),EXACT(MID(tab!$C40,1,LEN($A$2)),$A$2)),"",""""&$A$2&tab!$A40&"."&tab!$B40&""": """&SUBSTITUTE(tab!$C40,"""","\""")&""",") -> "layout.tab.header.Publication.conference.files": "Files",
B37: =IF(OR(ISBLANK(tab!$C41),EXACT(MID(tab!$C41,1,LEN($A$2)),$A$2)),"",""""&$A$2&tab!$A41&"."&tab!$B41&""": """&SUBSTITUTE(tab!$C41,"""","\""")&""",") -> "layout.tab.header.Publication.conference.conferencedetails": "Details",
B38: =IF(OR(ISBLANK(tab!$C43),EXACT(MID(tab!$C43,1,LEN($A$2)),$A$2)),"",""""&$A$2&tab!$A43&"."&tab!$B43&""": """&SUBSTITUTE(tab!$C43,"""","\""")&""",") -> "layout.tab.header.Publication.conference.statistics": "Metrics",
B39: =IF(OR(ISBLANK(tab!$C44),EXACT(MID(tab!$C44,1,LEN($A$2)),$A$2)),"",""""&$A$2&tab!$A44&"."&tab!$B44&""": """&SUBSTITUTE(tab!$C44,"""","\""")&""",") -> "layout.tab.header.Publication.media.mediamain": "Information",
B40: =IF(OR(ISBLANK(tab!$C45),EXACT(MID(tab!$C45,1,LEN($A$2)),$A$2)),"",""""&$A$2&tab!$A45&"."&tab!$B45&""": """&SUBSTITUTE(tab!$C45,"""","\""")&""",") -> "layout.tab.header.Publication.media.files": "Files",
B41: =IF(OR(ISBLANK(tab!$C46),EXACT(MID(tab!$C46,1,LEN($A$2)),$A$2)),"",""""&$A$2&tab!$A46&"."&tab!$B46&""": """&SUBSTITUTE(tab!$C46,"""","\""")&""",") -> "layout.tab.header.Publication.media.mediadetails": "Details",
B42: =IF(OR(ISBLANK(tab!$C48),EXACT(MID(tab!$C48,1,LEN($A$2)),$A$2)),"",""""&$A$2&tab!$A48&"."&tab!$B48&""": """&SUBSTITUTE(tab!$C48,"""","\""")&""",") -> "layout.tab.header.Publication.media.statistics": "Metrics",
B43: =IF(OR(ISBLANK(tab!$C49),EXACT(MID(tab!$C49,1,LEN($A$2)),$A$2)),"",""""&$A$2&tab!$A49&"."&tab!$B49&""": """&SUBSTITUTE(tab!$C49,"""","\""")&""",") -> "layout.tab.header.Publication.preprint.preprintmain": "Information",
B44: =IF(OR(ISBLANK(tab!$C50),EXACT(MID(tab!$C50,1,LEN($A$2)),$A$2)),"",""""&$A$2&tab!$A50&"."&tab!$B50&""": """&SUBSTITUTE(tab!$C50,"""","\""")&""",") -> "layout.tab.header.Publication.preprint.files": "Files",
...

Sheet box_i18n
A1: PREFIX | B1: AUTOGENERATED I18N keys
A2: layout.box.header. | B2: =IF(OR(ISBLANK(box!$E7),EXACT(MID(box!$E7,1,LEN($A$2)),$A$2)),"",""""&$A$2&box!$A7&"."&box!$D7&""": """&SUBSTITUTE(box!$E7,"""","\""")&""",")
B3: =IF(OR(ISBLANK(box!$E8),EXACT(MID(box!$E8,1,LEN($A$2)),$A$2)),"",""""&$A$2&box!$A8&"."&box!$D8&""": """&SUBSTITUTE(box!$E8,"""","\""")&""",")
B4: =IF(OR(ISBLANK(box!$E9),EXACT(MID(box!$E9,1,LEN($A$2)),$A$2)),"",""""&$A$2&box!$A9&"."&box!$D9&""": """&SUBSTITUTE(box!$E9,"""","\""")&""",")
B5: =IF(OR(ISBLANK(box!$E10),EXACT(MID(box!$E10,1,LEN($A$2)),$A$2)),"",""""&$A$2&box!$A10&"."&box!$D10&""": """&SUBSTITUTE(box!$E10,"""","\""")&""",")
B6: =IF(OR(ISBLANK(box!$E11),EXACT(MID(box!$E11,1,LEN($A$2)),$A$2)),"",""""&$A$2&box!$A11&"."&box!$D11&""": """&SUBSTITUTE(box!$E11,"""","\""")&""",") -> "layout.box.header.Person.usagemetrics": "Usage metrics",
B7: =IF(OR(ISBLANK(box!$E12),EXACT(MID(box!$E12,1,LEN($A$2)),$A$2)),"",""""&$A$2&box!$A12&"."&box!$D12&""": """&SUBSTITUTE(box!$E12,"""","\""")&""",") -> "layout.box.header.Person.metrics": "Metrics",
B8: =IF(OR(ISBLANK(box!$E14),EXACT(MID(box!$E14,1,LEN($A$2)),$A$2)),"",""""&$A$2&box!$A14&"."&box!$D14&""": """&SUBSTITUTE(box!$E14,"""","\""")&""",") -> "layout.box.header.Person.researcherprofile": "Profile",
B9: =IF(OR(ISBLANK(box!$E15),EXACT(MID(box!$E15,1,LEN($A$2)),$A$2)),"",""""&$A$2&box!$A15&"."&box!$D15&""": """&SUBSTITUTE(box!$E15,"""","\""")&""",") -> "layout.box.header.Person.projects": "Projects",
B10: =IF(OR(ISBLANK(box!$E16),EXACT(MID(box!$E16,1,LEN($A$2)),$A$2)),"",""""&$A$2&box!$A16&"."&box!$D16&""": """&SUBSTITUTE(box!$E16,"""","\""")&""",") -> "layout.box.header.Person.secure": "Secured box",
B11: =IF(OR(ISBLANK(box!$E17),EXACT(MID(box!$E17,1,LEN($A$2)),$A$2)),"",""""&$A$2&box!$A17&"."&box!$D17&""": """&SUBSTITUTE(box!$E17,"""","\""")&""",")
B12: =IF(OR(ISBLANK(box!$E18),EXACT(MID(box!$E18,1,LEN($A$2)),$A$2)),"",""""&$A$2&box!$A18&"."&box!$D18&""": """&SUBSTITUTE(box!$E18,"""","\""")&""",") -> "layout.box.header.OrgUnit.details": "Details",
B13: =IF(OR(ISBLANK(box!$E19),EXACT(MID(box!$E19,1,LEN($A$2)),$A$2)),"",""""&$A$2&box!$A19&"."&box!$D19&""": """&SUBSTITUTE(box!$E19,"""","\""")&""",") -> "layout.box.header.OrgUnit.description": "Description",
B14: =IF(OR(ISBLANK(box!$E20),EXACT(MID(box!$E20,1,LEN($A$2)),$A$2)),"",""""&$A$2&box!$A20&"."&box!$D20&""": """&SUBSTITUTE(box!$E20,"""","\""")&""",") -> "layout.box.header.OrgUnit.organizations": "Affiliated EPFL Units",
B15: =IF(OR(ISBLANK(box!$E21),EXACT(MID(box!$E21,1,LEN($A$2)),$A$2)),"",""""&$A$2&box!$A21&"."&box!$D21&""": """&SUBSTITUTE(box!$E21,"""","\""")&""",") -> "layout.box.header.OrgUnit.publications": "Scholarly works",
B16: =IF(OR(ISBLANK(box!$E22),EXACT(MID(box!$E22,1,LEN($A$2)),$A$2)),"",""""&$A$2&box!$A22&"."&box!$D22&""": """&SUBSTITUTE(box!$E22,"""","\""")&""",") -> "layout.box.header.OrgUnit.projects": "OrgUnit funded Projects",
B17: =IF(OR(ISBLANK(box!$E23),EXACT(MID(box!$E23,1,LEN($A$2)),$A$2)),"",""""&$A$2&box!$A23&"."&box!$D23&""": """&SUBSTITUTE(box!$E23,"""","\""")&""",") -> "layout.box.header.OrgUnit.rpprojects": "OrgUnit's Researchers projects",
B18: =IF(OR(ISBLANK(box!$E24),EXACT(MID(box!$E24,1,LEN($A$2)),$A$2)),"",""""&$A$2&box!$A24&"."&box!$D24&""": """&SUBSTITUTE(box!$E24,"""","\""")&""",") -> "layout.box.header.OrgUnit.people": "Members",
B19: =IF(OR(ISBLANK(box!$E25),EXACT(MID(box!$E25,1,LEN($A$2)),$A$2)),"",""""&$A$2&box!$A25&"."&box!$D25&""": """&SUBSTITUTE(box!$E25,"""","\""")&""",")
... B34: =IF(OR(ISBLANK(box!$E40),EXACT(MID(box!$E40,1,LEN($A$2)),$A$2)),"",""""&$A$2&box!$A40&"."&box!$D40&""": """&SUBSTITUTE(box!$E40,"""","\""")&""",")
B35: =IF(OR(ISBLANK(box!$E42),EXACT(MID(box!$E42,1,LEN($A$2)),$A$2)),"",""""&$A$2&box!$A42&"."&box!$D42&""": """&SUBSTITUTE(box!$E42,"""","\""")&""",")
B36: =IF(OR(ISBLANK(box!$E43),EXACT(MID(box!$E43,1,LEN($A$2)),$A$2)),"",""""&$A$2&box!$A43&"."&box!$D43&""": """&SUBSTITUTE(box!$E43,"""","\""")&""",")
B37: =IF(OR(ISBLANK(box!$E44),EXACT(MID(box!$E44,1,LEN($A$2)),$A$2)),"",""""&$A$2&box!$A44&"."&box!$D44&""": """&SUBSTITUTE(box!$E44,"""","\""")&""",")
B38: =IF(OR(ISBLANK(box!$E45),EXACT(MID(box!$E45,1,LEN($A$2)),$A$2)),"",""""&$A$2&box!$A45&"."&box!$D45&""": """&SUBSTITUTE(box!$E45,"""","\""")&""",")
B39: =IF(OR(ISBLANK(box!$E46),EXACT(MID(box!$E46,1,LEN($A$2)),$A$2)),"",""""&$A$2&box!$A46&"."&box!$D46&""": """&SUBSTITUTE(box!$E46,"""","\""")&""",")
B40: =IF(OR(ISBLANK(box!$E47),EXACT(MID(box!$E47,1,LEN($A$2)),$A$2)),"",""""&$A$2&box!$A47&"."&box!$D47&""": """&SUBSTITUTE(box!$E47,"""","\""")&""",")
B41: =IF(OR(ISBLANK(box!$E48),EXACT(MID(box!$E48,1,LEN($A$2)),$A$2)),"",""""&$A$2&box!$A48&"."&box!$D48&""": """&SUBSTITUTE(box!$E48,"""","\""")&""",")
B42: =IF(OR(ISBLANK(box!$E49),EXACT(MID(box!$E49,1,LEN($A$2)),$A$2)),"",""""&$A$2&box!$A49&"."&box!$D49&""": """&SUBSTITUTE(box!$E49,"""","\""")&""",")
B43: =IF(OR(ISBLANK(box!$E50),EXACT(MID(box!$E50,1,LEN($A$2)),$A$2)),"",""""&$A$2&box!$A50&"."&box!$D50&""": """&SUBSTITUTE(box!$E50,"""","\""")&""",")
B44: =IF(OR(ISBLANK(box!$E51),EXACT(MID(box!$E51,1,LEN($A$2)),$A$2)),"",""""&$A$2&box!$A51&"."&box!$D51&""": """&SUBSTITUTE(box!$E51,"""","\""")&""",")
B45: =IF(OR(ISBLANK(box!$E52),EXACT(MID(box!$E52,1,LEN($A$2)),$A$2)),"",""""&$A$2&box!$A52&"."&box!$D52&""": """&SUBSTITUTE(box!$E52,"""","\""")&""",")
B46: =IF(OR(ISBLANK(box!$E53),EXACT(MID(box!$E53,1,LEN($A$2)),$A$2)),"",""""&$A$2&box!$A53&"."&box!$D53&""": """&SUBSTITUTE(box!$E53,"""","\""")&""",")
... B55: =IF(OR(ISBLANK(box!$E62),EXACT(MID(box!$E62,1,LEN($A$2)),$A$2)),"",""""&$A$2&box!$A62&"."&box!$D62&""": """&SUBSTITUTE(box!$E62,"""","\""")&""",")
B56: =IF(OR(ISBLANK(box!$E64),EXACT(MID(box!$E64,1,LEN($A$2)),$A$2)),"",""""&$A$2&box!$A64&"."&box!$D64&""": """&SUBSTITUTE(box!$E64,"""","\""")&""",")
B57: =IF(OR(ISBLANK(box!$E65),EXACT(MID(box!$E65,1,LEN($A$2)),$A$2)),"",""""&$A$2&box!$A65&"."&box!$D65&""": """&SUBSTITUTE(box!$E65,"""","\""")&""",")
B58: =IF(OR(ISBLANK(box!$E66),EXACT(MID(box!$E66,1,LEN($A$2)),$A$2)),"",""""&$A$2&box!$A66&"."&box!$D66&""": """&SUBSTITUTE(box!$E66,"""","\""")&""",")
B59: =IF(OR(ISBLANK(box!$E67),EXACT(MID(box!$E67,1,LEN($A$2)),$A$2)),"",""""&$A$2&box!$A67&"."&box!$D67&""": """&SUBSTITUTE(box!$E67,"""","\""")&""",")
B60: =IF(OR(ISBLANK(box!$E68),EXACT(MID(box!$E68,1,LEN($A$2)),$A$2)),"",""""&$A$2&box!$A68&"."&box!$D68&""": """&SUBSTITUTE(box!$E68,"""","\""")&""",")
B61: =IF(OR(ISBLANK(box!$E69),EXACT(MID(box!$E69,1,LEN($A$2)),$A$2)),"",""""&$A$2&box!$A69&"."&box!$D69&""": """&SUBSTITUTE(box!$E69,"""","\""")&""",")
B62: =IF(OR(ISBLANK(box!$E70),EXACT(MID(box!$E70,1,LEN($A$2)),$A$2)),"",""""&$A$2&box!$A70&"."&box!$D70&""": """&SUBSTITUTE(box!$E70,"""","\""")&""",")
...

Sheet metadata_i18n
A1: PREFIX | B1: AUTOGENERATED I18N keys
A2: layout.field.label. | B2: =IF(ISBLANK(box2metadata!$I8),"",""""&$A$2&box2metadata!$A8&"."&IF(ISBLANK(box2metadata!$F8),box2metadata!$E8,box2metadata!$F8)&""": """&SUBSTITUTE(box2metadata!$I8,"""","\""")&""",")
B3: =IF(ISBLANK(box2metadata!$I9),"",""""&$A$2&box2metadata!$A9&"."&IF(ISBLANK(box2metadata!$F9),box2metadata!$E9,box2metadata!$F9)&""": """&SUBSTITUTE(box2metadata!$I9,"""","\""")&""",")
B4: =IF(ISBLANK(box2metadata!$I10),"",""""&$A$2&box2metadata!$A10&"."&IF(ISBLANK(box2metadata!$F10),box2metadata!$E10,box2metadata!$F10)&""": """&SUBSTITUTE(box2metadata!$I10,"""","\""")&""",") -> "layout.field.label.Person.dc.title": "Name",
B5: =IF(ISBLANK(box2metadata!$I11),"",""""&$A$2&box2metadata!$A11&"."&IF(ISBLANK(box2metadata!$F11),box2metadata!$E11,box2metadata!$F11)&""": """&SUBSTITUTE(box2metadata!$I11,"""","\""")&""",") -> "layout.field.label.Person.crisrp.name": "Official Name",
B6: =IF(ISBLANK(box2metadata!$I12),"",""""&$A$2&box2metadata!$A12&"."&IF(ISBLANK(box2metadata!$F12),box2metadata!$E12,box2metadata!$F12)&""": """&SUBSTITUTE(box2metadata!$I12,"""","\""")&""",") -> "layout.field.label.Person.crisrp.name.translated": "Translated name",
B7: =IF(ISBLANK(box2metadata!#ref!),"",""""&$A$2&box2metadata!#ref!&"."&IF(ISBLANK(box2metadata!#ref!),box2metadata!#ref!,box2metadata!#ref!)&""": """&SUBSTITUTE(box2metadata!#ref!,"""","\""")&""",") -> #NAME?
B8: =IF(ISBLANK(box2metadata!$I13),"",""""&$A$2&box2metadata!$A13&"."&IF(ISBLANK(box2metadata!$F13),box2metadata!$E13,box2metadata!$F13)&""": """&SUBSTITUTE(box2metadata!$I13,"""","\""")&""",") -> "layout.field.label.Person.person.jobTitle": "Main position",
B9: =IF(ISBLANK(box2metadata!$I14),"",""""&$A$2&box2metadata!$A14&"."&IF(ISBLANK(box2metadata!$F14),box2metadata!$E14,box2metadata!$F14)&""": """&SUBSTITUTE(box2metadata!$I14,"""","\""")&""",") -> "layout.field.label.Person.person.affiliation.name": "Main EPFL affiliation",
B10: =IF(ISBLANK(box2metadata!$I15),"",""""&$A$2&box2metadata!$A15&"."&IF(ISBLANK(box2metadata!$F15),box2metadata!$E15,box2metadata!$F15)&""": """&SUBSTITUTE(box2metadata!$I15,"""","\""")&""",") -> "layout.field.label.Person.person.email": "Email",
B11: =IF(ISBLANK(box2metadata!$I16),"",""""&$A$2&box2metadata!$A16&"."&IF(ISBLANK(box2metadata!$F16),box2metadata!$E16,box2metadata!$F16)&""": """&SUBSTITUTE(box2metadata!$I16,"""","\""")&""",") -> "layout.field.label.Person.person.identifier.orcid": "ORCID",
B12: =IF(ISBLANK(box2metadata!$I18),"",""""&$A$2&box2metadata!$A18&"."&IF(ISBLANK(box2metadata!$F18),box2metadata!$E18,box2metadata!$F18)&""": """&SUBSTITUTE(box2metadata!$I18,"""","\""")&""",") -> "layout.field.label.Person.person.identifier.scopus-author-id": "ScopusID",
B13: =IF(ISBLANK(box2metadata!$I19),"",""""&$A$2&box2metadata!$A19&"."&IF(ISBLANK(box2metadata!$F19),box2metadata!$E19,box2metadata!$F19)&""": """&SUBSTITUTE(box2metadata!$I19,"""","\""")&""",") -> "layout.field.label.Person.person.identifier.rid": "ResearcherID",
B14: =IF(ISBLANK(box2metadata!$I20),"",""""&$A$2&box2metadata!$A20&"."&IF(ISBLANK(box2metadata!$F20),box2metadata!$E20,box2metadata!$F20)&""": """&SUBSTITUTE(box2metadata!$I20,"""","\""")&""",") -> "layout.field.label.Person.epfl.sciper.active": "EPFL member",
B15: =IF(ISBLANK(box2metadata!$I21),"",""""&$A$2&box2metadata!$A21&"."&IF(ISBLANK(box2metadata!$F21),box2metadata!$E21,box2metadata!$F21)&""": """&SUBSTITUTE(box2metadata!$I21,"""","\""")&""",") -> "layout.field.label.Person.dc.description.abstract": "Biography",
B16: =IF(ISBLANK(box2metadata!$I22),"",""""&$A$2&box2metadata!$A22&"."&IF(ISBLANK(box2metadata!$F22),box2metadata!$E22,box2metadata!$F22)&""": """&SUBSTITUTE(box2metadata!$I22,"""","\""")&""",") -> "layout.field.label.Person.dc.subject": "Research Interests",
B17: =IF(ISBLANK(box2metadata!$I23),"",""""&$A$2&box2metadata!$A23&"."&IF(ISBLANK(box2metadata!$F23),box2metadata!$E23,box2metadata!$F23)&""": """&SUBSTITUTE(box2metadata!$I23,"""","\""")&""",") -> "layout.field.label.Person.oairecerif.identifier.url": "Personal website",
B18: =IF(ISBLANK(box2metadata!$I24),"",""""&$A$2&box2metadata!$A24&"."&IF(ISBLANK(box2metadata!$F24),box2metadata!$E24,box2metadata!$F24)&""": """&SUBSTITUTE(box2metadata!$I24,"""","\""")&""",") -> "layout.field.label.Person.oairecerif.person.affiliation": "EPFL affiliations",
B19: =IF(ISBLANK(box2metadata!$I25),"",""""&$A$2&box2metadata!$A25&"."&IF(ISBLANK(box2metadata!$F25),box2metadata!$E25,box2metadata!$F25)&""": """&SUBSTITUTE(box2metadata!$I25,"""","\""")&""",")
B20: =IF(ISBLANK(box2metadata!$I26),"",""""&$A$2&box2metadata!$A26&"."&IF(ISBLANK(box2metadata!$F26),box2metadata!$E26,box2metadata!$F26)&""": """&SUBSTITUTE(box2metadata!$I26,"""","\""")&""",")
B21: =IF(ISBLANK(box2metadata!$I27),"",""""&$A$2&box2metadata!$A27&"."&IF(ISBLANK(box2metadata!$F27),box2metadata!$E27,box2metadata!$F27)&""": """&SUBSTITUTE(box2metadata!$I27,"""","\""")&""",")
B22: =IF(ISBLANK(box2metadata!$I28),"",""""&$A$2&box2metadata!$A28&"."&IF(ISBLANK(box2metadata!$F28),box2metadata!$E28,box2metadata!$F28)&""": """&SUBSTITUTE(box2metadata!$I28,"""","\""")&""",") -> "layout.field.label.OrgUnit.oairecerif.acronym": "Acronym",
B23: =IF(ISBLANK(box2metadata!$I29),"",""""&$A$2&box2metadata!$A29&"."&IF(ISBLANK(box2metadata!$F29),box2metadata!$E29,box2metadata!$F29)&""": """&SUBSTITUTE(box2metadata!$I29,"""","\""")&""",") -> "layout.field.label.OrgUnit.epfl.unit.alias": "Other aliases",
... B63: =IF(ISBLANK(box2metadata!$I69),"",""""&$A$2&box2metadata!$A69&"."&IF(ISBLANK(box2metadata!$F69),box2metadata!$E69,box2metadata!$F69)&""": """&SUBSTITUTE(box2metadata!$I69,"""","\""")&""",") -> "layout.field.label.Publication.dc.relation.journal": "Journal title",
B64: =IF(ISBLANK(box2metadata!$I71),"",""""&$A$2&box2metadata!$A71&"."&IF(ISBLANK(box2metadata!$F71),box2metadata!$E71,box2metadata!$F71)&""": """&SUBSTITUTE(box2metadata!$I71,"""","\""")&""",") -> "layout.field.label.Publication.oaire.citation.volume": "Volume",
B65: =IF(ISBLANK(box2metadata!$I72),"",""""&$A$2&box2metadata!$A72&"."&IF(ISBLANK(box2metadata!$F72),box2metadata!$E72,box2metadata!$F72)&""": """&SUBSTITUTE(box2metadata!$I72,"""","\""")&""",") -> "layout.field.label.Publication.oaire.citation.issue": "Issue",
B66: =IF(ISBLANK(box2metadata!$I73),"",""""&$A$2&box2metadata!$A73&"."&IF(ISBLANK(box2metadata!$F73),box2metadata!$E73,box2metadata!$F73)&""": """&SUBSTITUTE(box2metadata!$I73,"""","\""")&""",") -> "layout.field.label.Publication.oaire.citation.articlenumber": "Article Number",
B67: =IF(ISBLANK(box2metadata!$I74),"",""""&$A$2&box2metadata!$A74&"."&IF(ISBLANK(box2metadata!$F74),box2metadata!$E74,box2metadata!$F74)&""": """&SUBSTITUTE(box2metadata!$I74,"""","\""")&""",") -> "layout.field.label.Publication.oaire.citation.startPage": "Start page",
B68: =IF(ISBLANK(box2metadata!$I75),"",""""&$A$2&box2metadata!$A75&"."&IF(ISBLANK(box2metadata!$F75),box2metadata!$E75,box2metadata!$F75)&""": """&SUBSTITUTE(box2metadata!$I75,"""","\""")&""",") -> "layout.field.label.Publication.oaire.citation.endPage": "End page",
B69: =IF(ISBLANK(box2metadata!$I76),"",""""&$A$2&box2metadata!$A76&"."&IF(ISBLANK(box2metadata!$F76),box2metadata!$E76,box2metadata!$F76)&""": """&SUBSTITUTE(box2metadata!$I76,"""","\""")&""",") -> "layout.field.label.Publication.dc.subject": "Subjects",
B70: =IF(ISBLANK(box2metadata!$I77),"",""""&$A$2&box2metadata!$A77&"."&IF(ISBLANK(box2metadata!$F77),box2metadata!$E77,box2metadata!$F77)&""": """&SUBSTITUTE(box2metadata!$I77,"""","\""")&""",") -> "layout.field.label.Publication.dc.description.notes": "Note",
B71: =IF(ISBLANK(box2metadata!$I78),"",""""&$A$2&box2metadata!$A78&"."&IF(ISBLANK(box2metadata!$F78),box2metadata!$E78,box2metadata!$F78)&""": """&SUBSTITUTE(box2metadata!$I78,"""","\""")&""",") -> "layout.field.label.Publication.epfl.url": "Additional link",
B72: =IF(ISBLANK(box2metadata!$I79),"",""""&$A$2&box2metadata!$A79&"."&IF(ISBLANK(box2metadata!$F79),box2metadata!$E79,box2metadata!$F79)&""": """&SUBSTITUTE(box2metadata!$I79,"""","\""")&""",") -> "layout.field.label.Publication.epfl.peerreviewed": "Peer reviewed",
B73: =IF(ISBLANK(box2metadata!$I81),"",""""&$A$2&box2metadata!$A81&"."&IF(ISBLANK(box2metadata!$F81),box2metadata!$E81,box2metadata!$F81)&""": """&SUBSTITUTE(box2metadata!$I81,"""","\""")&""",") -> "layout.field.label.Publication.dc.description.sponsorship": "EPFL units",
B74: =IF(ISBLANK(box2metadata!$I82),"",""""&$A$2&box2metadata!$A82&"."&IF(ISBLANK(box2metadata!$F82),box2metadata!$E82,box2metadata!$F82)&""": """&SUBSTITUTE(box2metadata!$I82,"""","\""")&""",")
B75: =IF(ISBLANK(box2metadata!$I83),"",""""&$A$2&box2metadata!$A83&"."&IF(ISBLANK(box2metadata!$F83),box2metadata!$E83,box2metadata!$F83)&""": """&SUBSTITUTE(box2metadata!$I83,"""","\""")&""",")
B76: =IF(ISBLANK(box2metadata!$I84),"",""""&$A$2&box2metadata!$A84&"."&IF(ISBLANK(box2metadata!$F84),box2metadata!$E84,box2metadata!$F84)&""": """&SUBSTITUTE(box2metadata!$I84,"""","\""")&""",") -> "layout.field.label.Publication.dc.date.available": "Available on Infoscience",
B77: =IF(ISBLANK(box2metadata!$I85),"",""""&$A$2&box2metadata!$A85&"."&IF(ISBLANK(box2metadata!$F85),box2metadata!$E85,box2metadata!$F85)&""": """&SUBSTITUTE(box2metadata!$I85,"""","\""")&""",") -> "layout.field.label.Publication.dc.identifier.uri": "Permanent URL",
B78: =IF(ISBLANK(box2metadata!$I86),"",""""&$A$2&box2metadata!$A86&"."&IF(ISBLANK(box2metadata!$F86),box2metadata!$E86,box2metadata!$F86)&""": """&SUBSTITUTE(box2metadata!$I86,"""","\""")&""",")
B79: =IF(ISBLANK(box2metadata!$I87),"",""""&$A$2&box2metadata!$A87&"."&IF(ISBLANK(box2metadata!$F87),box2metadata!$E87,box2metadata!$F87)&""": """&SUBSTITUTE(box2metadata!$I87,"""","\""")&""",")
...

Sheet metadatagroup_i18n
A1: PREFIX | B1: AUTOGENERATED I18N keys
A2: layout.field.label. | B2: =IF(ISBLANK(metadatagroups!$D4),"",""""&$A$2&metadatagroups!$A4&"."&metadatagroups!$D4&""": """&SUBSTITUTE(metadatagroups!$G4,"""","\""")&""",") -> "layout.field.label.Person.oairecerif.affiliation.role": "Position",
B3: =IF(ISBLANK(metadatagroups!$D5),"",""""&$A$2&metadatagroups!$A5&"."&metadatagroups!$D5&""": """&SUBSTITUTE(metadatagroups!$G5,"""","\""")&""",") -> "layout.field.label.Person.oairecerif.person.affiliation": "EPFL Unit",
B4: =IF(ISBLANK(metadatagroups!$D6),"",""""&$A$2&metadatagroups!$A6&"."&metadatagroups!$D6&""": """&SUBSTITUTE(metadatagroups!$G6,"""","\""")&""",") -> "layout.field.label.Person.oairecerif.affiliation.endDate": "Affiliation end date",
B5: =IF(ISBLANK(metadatagroups!$D7),"",""""&$A$2&metadatagroups!$A7&"."&metadatagroups!$D7&""": """&SUBSTITUTE(metadatagroups!$G7,"""","\""")&""",") -> "layout.field.label.Publication.dc.date.issued": "",
B6: =IF(ISBLANK(metadatagroups!$D8),"",""""&$A$2&metadatagroups!$A8&"."&metadatagroups!$D8&""": """&SUBSTITUTE(metadatagroups!$G8,"""","\""")&""",") -> "layout.field.label.Publication.dc.relation.ispartof": "",
B7: =IF(ISBLANK(metadatagroups!$D9),"",""""&$A$2&metadatagroups!$A9&"."&metadatagroups!$D9&""": """&SUBSTITUTE(metadatagroups!$G9,"""","\""")&""",") -> "layout.field.label.Publication.dc.date.issued": "",
B8: =IF(ISBLANK(metadatagroups!$D10),"",""""&$A$2&metadatagroups!$A10&"."&metadatagroups!$D10&""": """&SUBSTITUTE(metadatagroups!$G10,"""","\""")&""",") -> "layout.field.label.Publication.dc.relation.journal": "",
B9: =IF(ISBLANK(metadatagroups!$D11),"",""""&$A$2&metadatagroups!$A11&"."&metadatagroups!$D11&""": """&SUBSTITUTE(metadatagroups!$G11,"""","\""")&""",") -> "layout.field.label.Publication.epfl.url.description": "Additional link",
B10: =IF(ISBLANK(metadatagroups!$D12),"",""""&$A$2&metadatagroups!$A12&"."&metadatagroups!$D12&""": """&SUBSTITUTE(metadatagroups!$G12,"""","\""")&""",") -> "layout.field.label.Publication.epfl.url": "",
B11: =IF(ISBLANK(metadatagroups!$D13),"",""""&$A$2&metadatagroups!$A13&"."&metadatagroups!$D13&""": """&SUBSTITUTE(metadatagroups!$G13,"""","\""")&""",") -> "layout.field.label.Publication.oairecerif.funder": "Funder",
B12: =IF(ISBLANK(metadatagroups!$D14),"",""""&$A$2&metadatagroups!$A14&"."&metadatagroups!$D14&""": """&SUBSTITUTE(metadatagroups!$G14,"""","\""")&""",") -> "layout.field.label.Publication.dc.relation.funding": "Grant Name",
B13: =IF(ISBLANK(metadatagroups!$D15),"",""""&$A$2&metadatagroups!$A15&"."&metadatagroups!$D15&""": """&SUBSTITUTE(metadatagroups!$G15,"""","\""")&""",") -> "layout.field.label.Publication.dc.relation.grantno": "Grant Number",
B14: =IF(ISBLANK(metadatagroups!$D16),"",""""&$A$2&metadatagroups!$A16&"."&metadatagroups!$D16&""": """&SUBSTITUTE(metadatagroups!$G16,"""","\""")&""",") -> "layout.field.label.Publication.crisfund.award.uri": "Grant URL",
B15: =IF(ISBLANK(metadatagroups!$D19),"",""""&$A$2&metadatagroups!$A19&"."&metadatagroups!$D19&""": """&SUBSTITUTE(metadatagroups!$G19,"""","\""")&""",") -> "layout.field.label.Publication.dc.relation.conference": "Event name",
B16: =IF(ISBLANK(metadatagroups!$D20),"",""""&$A$2&metadatagroups!$A20&"."&metadatagroups!$D20&""": """&SUBSTITUTE(metadatagroups!$G20,"""","\""")&""",") -> "layout.field.label.Publication.oairecerif.acronym": "Event acronym",
B17: =IF(ISBLANK(metadatagroups!$D21),"",""""&$A$2&metadatagroups!$A21&"."&metadatagroups!$D21&""": """&SUBSTITUTE(metadatagroups!$G21,"""","\""")&""",") -> "layout.field.label.Publication.oaire.citation.conferencePlace": "Event place",
B18: =IF(ISBLANK(metadatagroups!$D22),"",""""&$A$2&metadatagroups!$A22&"."&metadatagroups!$D22&""": """&SUBSTITUTE(metadatagroups!$G22,"""","\""")&""",") -> "layout.field.label.Publication.oaire.citation.conferenceDate": "Event date",
B19: =IF(ISBLANK(metadatagroups!$D23),"",""""&$A$2&metadatagroups!$A23&"."&metadatagroups!$D23&""": """&SUBSTITUTE(metadatagroups!$G23,"""","\""")&""",") -> "layout.field.label.Publication.epfl.award": "Award",
B20: =IF(ISBLANK(metadatagroups!$D24),"",""""&$A$2&metadatagroups!$A24&"."&metadatagroups!$D24&""": """&SUBSTITUTE(metadatagroups!$G24,"""","\""")&""",") -> "layout.field.label.Publication.epfl.award.date": "",
B21: =IF(ISBLANK(metadatagroups!$D25),"",""""&$A$2&metadatagroups!$A25&"."&metadatagroups!$D25&""": """&SUBSTITUTE(metadatagroups!$G25,"""","\""")&""",") -> "layout.field.label.Publication.datacite.relationType": "Relation",
B22: =IF(ISBLANK(metadatagroups!$D26),"",""""&$A$2&metadatagroups!$A26&"."&metadatagroups!$D26&""": """&SUBSTITUTE(metadatagroups!$G26,"""","\""")&""",") -> "layout.field.label.Publication.dc.relation.title": "Related work",
B23: =IF(ISBLANK(metadatagroups!$D27),"",""""&$A$2&metadatagroups!$A27&"."&metadatagroups!$D27&""": """&SUBSTITUTE(metadatagroups!$G27,"""","\""")&""",") -> "layout.field.label.Publication.datacite.relatedIdentifier": "URL/DOI",
B24: =IF(ISBLANK(metadatagroups!$D28),"",""""&$A$2&metadatagroups!$A28&"."&metadatagroups!$D28&""": """&SUBSTITUTE(metadatagroups!$G28,"""","\""")&""",") -> "layout.field.label.Product.dc.type": "",
B25: =IF(ISBLANK(metadatagroups!$D29),"",""""&$A$2&metadatagroups!$A29&"."&metadatagroups!$D29&""": """&SUBSTITUTE(metadatagroups!$G29,"""","\""")&""",") -> "layout.field.label.Product.datacite.rights": "",
B26: =IF(ISBLANK(metadatagroups!$D32),"",""""&$A$2&metadatagroups!$A32&"."&metadatagroups!$D32&""": """&SUBSTITUTE(metadatagroups!$G32,"""","\""")&""",") -> "layout.field.label.Product.dc.date.issued": "",
B27: =IF(ISBLANK(metadatagroups!$D33),"",""""&$A$2&metadatagroups!$A33&"."&metadatagroups!$D33&""": """&SUBSTITUTE(metadatagroups!$G33,"""","\""")&""",") -> "layout.field.label.Product.dc.publisher": "",
B28: =IF(ISBLANK(metadatagroups!$D34),"",""""&$A$2&metadatagroups!$A34&"."&metadatagroups!$D34&""": """&SUBSTITUTE(metadatagroups!$G34,"""","\""")&""",") -> "layout.field.label.Product.epfl.url.description": "Link description",
B29: =IF(ISBLANK(metadatagroups!$D35),"",""""&$A$2&metadatagroups!$A35&"."&metadatagroups!$D35&""": """&SUBSTITUTE(metadatagroups!$G35,"""","\""")&""",") -> "layout.field.label.Product.epfl.url": "URL",
B30: =IF(ISBLANK(metadatagroups!$D36),"",""""&$A$2&metadatagroups!$A36&"."&metadatagroups!$D36&""": """&SUBSTITUTE(metadatagroups!$G36,"""","\""")&""",") -> "layout.field.label.Product.dc.relation.conference": "Event name",
B31: =IF(ISBLANK(metadatagroups!$D37),"",""""&$A$2&metadatagroups!$A37&"."&metadatagroups!$D37&""": """&SUBSTITUTE(metadatagroups!$G37,"""","\""")&""",") -> "layout.field.label.Product.oairecerif.acronym": "Event acronym",
B32: =IF(ISBLANK(metadatagroups!$D38),"",""""&$A$2&metadatagroups!$A38&"."&metadatagroups!$D38&""": """&SUBSTITUTE(metadatagroups!$G38,"""","\""")&""",") -> "layout.field.label.Product.oaire.citation.conferencePlace": "Event place",
B33: =IF(ISBLANK(metadatagroups!$D39),"",""""&$A$2&metadatagroups!$A39&"."&metadatagroups!$D39&""": """&SUBSTITUTE(metadatagroups!$G39,"""","\""")&""",") -> "layout.field.label.Product.oaire.citation.conferenceDate": "Event date",
B34: =IF(ISBLANK(metadatagroups!$D40),"",""""&$A$2&metadatagroups!$A40&"."&metadatagroups!$D40&""": """&SUBSTITUTE(metadatagroups!$G40,"""","\""")&""",") -> "layout.field.label.Product.oairecerif.funder": "Funder",
B35: =IF(ISBLANK(metadatagroups!$D41),"",""""&$A$2&metadatagroups!$A41&"."&metadatagroups!$D41&""": """&SUBSTITUTE(metadatagroups!$G41,"""","\""")&""",") -> "layout.field.label.Product.dc.relation.funding": "Grant Name",
B36: =IF(ISBLANK(metadatagroups!$D42),"",""""&$A$2&metadatagroups!$A42&"."&metadatagroups!$D42&""": """&SUBSTITUTE(metadatagroups!$G42,"""","\""")&""",") -> "layout.field.label.Product.dc.relation.grantno": "Grant Number",
B37: =IF(ISBLANK(metadatagroups!$D43),"",""""&$A$2&metadatagroups!$A43&"."&metadatagroups!$D43&""": """&SUBSTITUTE(metadatagroups!$G43,"""","\""")&""",") -> "layout.field.label.Product.crisfund.award.uri": "Grant URL",
... B43: =IF(ISBLANK(metadatagroups!$D49),"",""""&$A$2&metadatagroups!$A49&"."&metadatagroups!$D49&""": """&SUBSTITUTE(metadatagroups!$G49,"""","\""")&""",") -> "layout.field.label.Patent.datacite.available": "",
B44: =IF(ISBLANK(metadatagroups!$D52),"",""""&$A$2&metadatagroups!$A52&"."&metadatagroups!$D52&""": """&SUBSTITUTE(metadatagroups!$G52,"""","\""")&""",") -> "layout.field.label.Patent.epfl.url.description": "Additional link",
B45: =IF(ISBLANK(metadatagroups!$D53),"",""""&$A$2&metadatagroups!$A53&"."&metadatagroups!$D53&""": """&SUBSTITUTE(metadatagroups!$G53,"""","\""")&""",") -> "layout.field.label.Patent.epfl.url": "",
...
